Workbook
Name Slicer_cuisine_type: #N/A
Name Slicer_day_of_the_week: #N/A
Name Slicer_rating: #N/A

Sheet Dashboard
A1: 🍔 FOOD DELIVERY ANALYTICS DASHBOARD
A4: TOTAL ORDERS | C4: TOTAL ORDER VALUE | E4: AVG ORDER COST | G4: AVG RATING | I4: AVG DELIVERY TIME
A5: ='Pivot Tables'!J2 -> 200 | C5: ='Pivot Tables'!K2 -> 3575.66 | E5: ='Pivot Tables'!L2 -> 17.8783 | G5: ='Pivot Tables'!M2 -> 4.3474576 | I5: ='Pivot Tables'!N2 -> 24.19

Sheet Raw_Data
A1: order_id | B1: customer_id | C1: restaurant_name | D1: cuisine_type | E1: cost_of_the_order | F1: day_of_the_week | G1: rating | H1: food_preparation_time | I1: delivery_time
A2: 1477147 | B2: 337525 | C2: Hangawi | D2: Korean | E2: 30.75 | F2: Weekend | G2: Not given | H2: 25 | I2: 20
A3: 1477685 | B3: 358141 | C3: Blue Ribbon Sushi Izakaya | D3: Japanese | E3: 12.08 | F3: Weekend | G3: Not given | H3: 25 | I3: 23
A4: 1477070 | B4: 66393 | C4: Cafe Habana | D4: Mexican | E4: 12.23 | F4: Weekday | G4: 5 | H4: 23 | I4: 28
A5: 1477334 | B5: 106968 | C5: Blue Ribbon Fried Chicken | D5: American | E5: 29.2 | F5: Weekend | G5: 3 | H5: 25 | I5: 15
A6: 1478249 | B6: 76942 | C6: Dirty Bird to Go | D6: American | E6: 11.59 | F6: Weekday | G6: 4 | H6: 25 | I6: 24
A7: 1477224 | B7: 147468 | C7: Tamarind TriBeCa | D7: Indian | E7: 25.22 | F7: Weekday | G7: 3 | H7: 20 | I7: 24
A8: 1477894 | B8: 157711 | C8: The Meatball Shop | D8: Italian | E8: 6.07 | F8: Weekend | G8: Not given | H8: 28 | I8: 21
A9: 1477859 | B9: 89574 | C9: Barbounia | D9: Mediterranean | E9: 5.97 | F9: Weekday | G9: 3 | H9: 33 | I9: 30
A10: 1477174 | B10: 121706 | C10: Anjappar Chettinad | D10: Indian | E10: 16.44 | F10: Weekday | G10: 5 | H10: 21 | I10: 26
A11: 1477311 | B11: 39705 | C11: Bukhara Grill | D11: Indian | E11: 7.18 | F11: Weekday | G11: 5 | H11: 29 | I11: 26
A12: 1477895 | B12: 143926 | C12: Big Wong Restaurant ÂŒ_Â¤Â¾Ã‘Â¼ | D12: Chinese | E12: 5.92 | F12: Weekday | G12: Not given | H12: 34 | I12: 28
A13: 1478437 | B13: 221206 | C13: Empanada Mama (closed) | D13: Mexican | E13: 8.1 | F13: Weekend | G13: 5 | H13: 23 | I13: 22
A14: 1476966 | B14: 129969 | C14: Blue Ribbon Fried Chicken | D14: American | E14: 24.3 | F14: Weekend | G14: 5 | H14: 23 | I14: 17
A15: 1477449 | B15: 104548 | C15: Pylos | D15: Mediterranean | E15: 11.3 | F15: Weekend | G15: 3 | H15: 24 | I15: 23
A16: 1478198 | B16: 62667 | C16: Lucky's Famous Burgers | D16: American | E16: 12.13 | F16: Weekday | G16: Not given | H16: 23 | I16: 30
A17: 1477414 | B17: 66222 | C17: Shake Shack | D17: American | E17: 16.2 | F17: Weekend | G17: 5 | H17: 33 | I17: 25
A18: 1477486 | B18: 104555 | C18: Sushi of Gari | D18: Japanese | E18: 16.98 | F18: Weekend | G18: Not given | H18: 30 | I18: 16
A19: 1477373 | B19: 139885 | C19: Blue Ribbon Sushi Izakaya | D19: Japanese | E19: 33.03 | F19: Weekend | G19: Not given | H19: 21 | I19: 22
A20: 1477138 | B20: 47280 | C20: RedFarm Hudson | D20: Chinese | E20: 14.12 | F20: Weekend | G20: 4 | H20: 25 | I20: 24
A21: 1477354 | B21: 67487 | C21: Blue Ribbon Sushi | D21: Japanese | E21: 16.2 | F21: Weekend | G21: 4 | H21: 35 | I21: 26
A22: 1478296 | B22: 250494 | C22: Five Guys Burgers and Fries | D22: American | E22: 24.2 | F22: Weekend | G22: 4 | H22: 21 | I22: 24
A23: 1478226 | B23: 137565 | C23: Shake Shack | D23: American | E23: 15.91 | F23: Weekend | G23: Not given | H23: 25 | I23: 20
A24: 1478287 | B24: 150599 | C24: Shake Shack | D24: American | E24: 29.1 | F24: Weekday | G24: 5 | H24: 21 | I24: 30
A25: 1478014 | B25: 54630 | C25: Tortaria | D25: Mexican | E25: 8.92 | F25: Weekend | G25: Not given | H25: 33 | I25: 16
A26: 1476714 | B26: 363783 | C26: Cafe Mogador | D26: Middle Eastern | E26: 15.86 | F26: Weekday | G26: Not given | H26: 32 | I26: 29
A27: 1476693 | B27: 41877 | C27: Cafe Mogador | D27: Middle Eastern | E27: 29.1 | F27: Weekday | G27: 5 | H27: 20 | I27: 29
A28: 1476995 | B28: 371590 | C28: The Meatball Shop | D28: Italian | E28: 21.88 | F28: Weekday | G28: 5 | H28: 24 | I28: 27
A29: 1476844 | B29: 175290 | C29: Otto Enoteca Pizzeria | D29: Italian | E29: 14.02 | F29: Weekend | G29: Not given | H29: 24 | I29: 16
A30: 1477015 | B30: 76686 | C30: Vezzo Thin Crust Pizza | D30: Italian | E30: 9.17 | F30: Weekend | G30: Not given | H30: 21 | I30: 24
A31: 1476889 | B31: 149984 | C31: Sushi of Gari 46 | D31: Japanese | E31: 12.18 | F31: Weekday | G31: Not given | H31: 20 | I31: 29
A32: 1478289 | B32: 318874 | C32: The Kati Roll Company | D32: Indian | E32: 31.33 | F32: Weekend | G32: 5 | H32: 28 | I32: 25
A33: 1477699 | B33: 302790 | C33: Klong | D33: Thai | E33: 29.05 | F33: Weekend | G33: 5 | H33: 35 | I33: 24
A34: 1476855 | B34: 317794 | C34: 5 Napkin Burger | D34: American | E34: 8.39 | F34: Weekday | G34: Not given | H34: 35 | I34: 24
A35: 1477748 | B35: 105349 | C35: TAO | D35: Japanese | E35: 9.12 | F35: Weekend | G35: Not given | H35: 34 | I35: 18
A36: 1478244 | B36: 181782 | C36: Parm | D36: Italian | E36: 29.1 | F36: Weekend | G36: 5 | H36: 30 | I36: 26
A37: 1478310 | B37: 65224 | C37: Sushi Samba | D37: Japanese | E37: 15.47 | F37: Weekend | G37: Not given | H37: 32 | I37: 26
A38: 1478017 | B38: 148649 | C38: Blue Ribbon Sushi | D38: Japanese | E38: 16.01 | F38: Weekday | G38: 4 | H38: 23 | I38: 31
A39: 1476871 | B39: 118709 | C39: The Meatball Shop | D39: Italian | E39: 24.3 | F39: Weekday | G39: 4 | H39: 31 | I39: 29
A40: 1477999 | B40: 208020 | C40: Haru Gramercy Park | D40: Japanese | E40: 29.83 | F40: Weekday | G40: 5 | H40: 20 | I40: 32
...

Sheet Cleaned_Data
A1: order_id | B1: customer_id | C1: restaurant_name | D1: cuisine_type | E1: cost_of_the_order | F1: day_of_the_week | G1: rating | H1: food_preparation_time | I1: delivery_time
A2: 1477147 | B2: 337525 | C2: Hangawi | D2: Korean | E2: 30.75 | F2: Weekend | G2: N/A | H2: 25 | I2: 20
A3: 1477685 | B3: 358141 | C3: Blue Ribbon Sushi Izakaya | D3: Japanese | E3: 12.08 | F3: Weekend | G3: N/A | H3: 25 | I3: 23
A4: 1477070 | B4: 66393 | C4: Cafe Habana | D4: Mexican | E4: 12.23 | F4: Weekday | G4: 5 | H4: 23 | I4: 28
A5: 1477334 | B5: 106968 | C5: Blue Ribbon Fried Chicken | D5: American | E5: 29.2 | F5: Weekend | G5: 3 | H5: 25 | I5: 15
A6: 1478249 | B6: 76942 | C6: Dirty Bird to Go | D6: American | E6: 11.59 | F6: Weekday | G6: 4 | H6: 25 | I6: 24
A7: 1477224 | B7: 147468 | C7: Tamarind TriBeCa | D7: Indian | E7: 25.22 | F7: Weekday | G7: 3 | H7: 20 | I7: 24
A8: 1477894 | B8: 157711 | C8: The Meatball Shop | D8: Italian | E8: 6.07 | F8: Weekend | G8: N/A | H8: 28 | I8: 21
A9: 1477859 | B9: 89574 | C9: Barbounia | D9: Mediterranean | E9: 5.97 | F9: Weekday | G9: 3 | H9: 33 | I9: 30
A10: 1477174 | B10: 121706 | C10: Anjappar Chettinad | D10: Indian | E10: 16.44 | F10: Weekday | G10: 5 | H10: 21 | I10: 26
A11: 1477311 | B11: 39705 | C11: Bukhara Grill | D11: Indian | E11: 7.18 | F11: Weekday | G11: 5 | H11: 29 | I11: 26
A12: 1477895 | B12: 143926 | C12: Big Wong Restaurant ÂŒ_Â¤Â¾Ã‘Â¼ | D12: Chinese | E12: 5.92 | F12: Weekday | G12: N/A | H12: 34 | I12: 28
A13: 1478437 | B13: 221206 | C13: Empanada Mama (closed) | D13: Mexican | E13: 8.1 | F13: Weekend | G13: 5 | H13: 23 | I13: 22
A14: 1476966 | B14: 129969 | C14: Blue Ribbon Fried Chicken | D14: American | E14: 24.3 | F14: Weekend | G14: 5 | H14: 23 | I14: 17
A15: 1477449 | B15: 104548 | C15: Pylos | D15: Mediterranean | E15: 11.3 | F15: Weekend | G15: 3 | H15: 24 | I15: 23
A16: 1478198 | B16: 62667 | C16: Lucky's Famous Burgers | D16: American | E16: 12.13 | F16: Weekday | G16: N/A | H16: 23 | I16: 30
A17: 1477414 | B17: 66222 | C17: Shake Shack | D17: American | E17: 16.2 | F17: Weekend | G17: 5 | H17: 33 | I17: 25
A18: 1477486 | B18: 104555 | C18: Sushi of Gari | D18: Japanese | E18: 16.98 | F18: Weekend | G18: N/A | H18: 30 | I18: 16
A19: 1477373 | B19: 139885 | C19: Blue Ribbon Sushi Izakaya | D19: Japanese | E19: 33.03 | F19: Weekend | G19: N/A | H19: 21 | I19: 22
A20: 1477138 | B20: 47280 | C20: RedFarm Hudson | D20: Chinese | E20: 14.12 | F20: Weekend | G20: 4 | H20: 25 | I20: 24
A21: 1477354 | B21: 67487 | C21: Blue Ribbon Sushi | D21: Japanese | E21: 16.2 | F21: Weekend | G21: 4 | H21: 35 | I21: 26
A22: 1478296 | B22: 250494 | C22: Five Guys Burgers and Fries | D22: American | E22: 24.2 | F22: Weekend | G22: 4 | H22: 21 | I22: 24
A23: 1478226 | B23: 137565 | C23: Shake Shack | D23: American | E23: 15.91 | F23: Weekend | G23: N/A | H23: 25 | I23: 20
A24: 1478287 | B24: 150599 | C24: Shake Shack | D24: American | E24: 29.1 | F24: Weekday | G24: 5 | H24: 21 | I24: 30
A25: 1478014 | B25: 54630 | C25: Tortaria | D25: Mexican | E25: 8.92 | F25: Weekend | G25: N/A | H25: 33 | I25: 16
A26: 1476714 | B26: 363783 | C26: Cafe Mogador | D26: Middle Eastern | E26: 15.86 | F26: Weekday | G26: N/A | H26: 32 | I26: 29
A27: 1476693 | B27: 41877 | C27: Cafe Mogador | D27: Middle Eastern | E27: 29.1 | F27: Weekday | G27: 5 | H27: 20 | I27: 29
A28: 1476995 | B28: 371590 | C28: The Meatball Shop | D28: Italian | E28: 21.88 | F28: Weekday | G28: 5 | H28: 24 | I28: 27
A29: 1476844 | B29: 175290 | C29: Otto Enoteca Pizzeria | D29: Italian | E29: 14.02 | F29: Weekend | G29: N/A | H29: 24 | I29: 16
A30: 1477015 | B30: 76686 | C30: Vezzo Thin Crust Pizza | D30: Italian | E30: 9.17 | F30: Weekend | G30: N/A | H30: 21 | I30: 24
A31: 1476889 | B31: 149984 | C31: Sushi of Gari 46 | D31: Japanese | E31: 12.18 | F31: Weekday | G31: N/A | H31: 20 | I31: 29
A32: 1478289 | B32: 318874 | C32: The Kati Roll Company | D32: Indian | E32: 31.33 | F32: Weekend | G32: 5 | H32: 28 | I32: 25
A33: 1477699 | B33: 302790 | C33: Klong | D33: Thai | E33: 29.05 | F33: Weekend | G33: 5 | H33: 35 | I33: 24
A34: 1476855 | B34: 317794 | C34: 5 Napkin Burger | D34: American | E34: 8.39 | F34: Weekday | G34: N/A | H34: 35 | I34: 24
A35: 1477748 | B35: 105349 | C35: TAO | D35: Japanese | E35: 9.12 | F35: Weekend | G35: N/A | H35: 34 | I35: 18
A36: 1478244 | B36: 181782 | C36: Parm | D36: Italian | E36: 29.1 | F36: Weekend | G36: 5 | H36: 30 | I36: 26
A37: 1478310 | B37: 65224 | C37: Sushi Samba | D37: Japanese | E37: 15.47 | F37: Weekend | G37: N/A | H37: 32 | I37: 26
A38: 1478017 | B38: 148649 | C38: Blue Ribbon Sushi | D38: Japanese | E38: 16.01 | F38: Weekday | G38: 4 | H38: 23 | I38: 31
A39: 1476871 | B39: 118709 | C39: The Meatball Shop | D39: Italian | E39: 24.3 | F39: Weekday | G39: 4 | H39: 31 | I39: 29
A40: 1477999 | B40: 208020 | C40: Haru Gramercy Park | D40: Japanese | E40: 29.83 | F40: Weekday | G40: 5 | H40: 20 | I40: 32
...

Sheet Analysis
A1: Order ID | B1: Restaurant | C1: Cuisine | D1: Delivery Time | E1: Delivery Category
A2: 1477147 | B2: =VLOOKUP(A2,Cleaned_Data!A:I,3,FALSE) -> Hangawi | C2: =INDEX(Cleaned_Data!D:D,MATCH(A2,Cleaned_Data!A:A,0)) -> Korean | D2: =VLOOKUP(A2,Cleaned_Data!A:I,9,FALSE) -> 20 | E2: =IF(D2<=20,"Fast",IF(D2<=30,"Normal","Slow")) -> Fast
A3: 1477685 | B3: =VLOOKUP(A3,Cleaned_Data!A:I,3,FALSE) -> Blue Ribbon Sushi Izakaya | C3: =INDEX(Cleaned_Data!D:D,MATCH(A3,Cleaned_Data!A:A,0)) -> Japanese | D3: =VLOOKUP(A3,Cleaned_Data!A:I,9,FALSE) -> 23 | E3: =IF(D3<=20,"Fast",IF(D3<=30,"Normal","Slow")) -> Normal
A4: 1477070 | B4: =VLOOKUP(A4,Cleaned_Data!A:I,3,FALSE) -> Cafe Habana | C4: =INDEX(Cleaned_Data!D:D,MATCH(A4,Cleaned_Data!A:A,0)) -> Mexican | D4: =VLOOKUP(A4,Cleaned_Data!A:I,9,FALSE) -> 28 | E4: =IF(D4<=20,"Fast",IF(D4<=30,"Normal","Slow")) -> Normal
A5: 1477334 | B5: =VLOOKUP(A5,Cleaned_Data!A:I,3,FALSE) -> Blue Ribbon Fried Chicken | C5: =INDEX(Cleaned_Data!D:D,MATCH(A5,Cleaned_Data!A:A,0)) -> American | D5: =VLOOKUP(A5,Cleaned_Data!A:I,9,FALSE) -> 15 | E5: =IF(D5<=20,"Fast",IF(D5<=30,"Normal","Slow")) -> Fast
A6: 1478249 | B6: =VLOOKUP(A6,Cleaned_Data!A:I,3,FALSE) -> Dirty Bird to Go | C6: =INDEX(Cleaned_Data!D:D,MATCH(A6,Cleaned_Data!A:A,0)) -> American | D6: =VLOOKUP(A6,Cleaned_Data!A:I,9,FALSE) -> 24 | E6: =IF(D6<=20,"Fast",IF(D6<=30,"Normal","Slow")) -> Normal
A7: 1477224 | B7: =VLOOKUP(A7,Cleaned_Data!A:I,3,FALSE) -> Tamarind TriBeCa | C7: =INDEX(Cleaned_Data!D:D,MATCH(A7,Cleaned_Data!A:A,0)) -> Indian | D7: =VLOOKUP(A7,Cleaned_Data!A:I,9,FALSE) -> 24 | E7: =IF(D7<=20,"Fast",IF(D7<=30,"Normal","Slow")) -> Normal
A8: 1477894 | B8: =VLOOKUP(A8,Cleaned_Data!A:I,3,FALSE) -> The Meatball Shop | C8: =INDEX(Cleaned_Data!D:D,MATCH(A8,Cleaned_Data!A:A,0)) -> Italian | D8: =VLOOKUP(A8,Cleaned_Data!A:I,9,FALSE) -> 21 | E8: =IF(D8<=20,"Fast",IF(D8<=30,"Normal","Slow")) -> Normal
A9: 1477859 | B9: =VLOOKUP(A9,Cleaned_Data!A:I,3,FALSE) -> Barbounia | C9: =INDEX(Cleaned_Data!D:D,MATCH(A9,Cleaned_Data!A:A,0)) -> Mediterranean | D9: =VLOOKUP(A9,Cleaned_Data!A:I,9,FALSE) -> 30 | E9: =IF(D9<=20,"Fast",IF(D9<=30,"Normal","Slow")) -> Normal
A10: 1477174 | B10: =VLOOKUP(A10,Cleaned_Data!A:I,3,FALSE) -> Anjappar Chettinad | C10: =INDEX(Cleaned_Data!D:D,MATCH(A10,Cleaned_Data!A:A,0)) -> Indian | D10: =VLOOKUP(A10,Cleaned_Data!A:I,9,FALSE) -> 26 | E10: =IF(D10<=20,"Fast",IF(D10<=30,"Normal","Slow")) -> Normal
A11: 1477311 | B11: =VLOOKUP(A11,Cleaned_Data!A:I,3,FALSE) -> Bukhara Grill | C11: =INDEX(Cleaned_Data!D:D,MATCH(A11,Cleaned_Data!A:A,0)) -> Indian | D11: =VLOOKUP(A11,Cleaned_Data!A:I,9,FALSE) -> 26 | E11: =IF(D11<=20,"Fast",IF(D11<=30,"Normal","Slow")) -> Normal

Sheet Pivot Tables
J1: Count of order_id | K1: Sum of cost_of_the_order | L1: Average of cost_of_the_order2 | M1: Average of rating | N1: Average of delivery_time
J2: 200 | K2: 3575.66 | L2: 17.8783 | M2: 4.3474576 | N2: 24.19
A3: Row Labels | B3: Count of order_id
A4: American | B4: 60
A5: Chinese | B5: 25
A6: French | B6: 1
A7: Indian | B7: 11
A8: Italian | B8: 33
A9: Japanese | B9: 42
A10: Korean | B10: 1
A11: Mediterranean | B11: 6
A12: Mexican | B12: 10
A13: Middle Eastern | B13: 3
A14: Southern | B14: 3
A15: Spanish | B15: 1
... A17: Grand Total | B17: 200
A20: Row Labels | B20: Count of order_id | D20: Row Labels | E20: Count of order_id | G20: Row Labels | H20: Count of order_id
A21: Blue Ribbon Fried Chicken | B21: 15 | D21: Weekday | E21: 64 | G21: 3 | H21: 19
A22: RedFarm Broadway | B22: 9 | D22: Weekend | E22: 136 | G22: 4 | H22: 39
A23: Shake Shack | B23: 22 | D23: Grand Total | E23: 200 | G23: 5 | H23: 60
A24: TAO | B24: 8 | G24: N/A | H24: 82
A25: The Meatball Shop | B25: 15 | G25: Grand Total | H25: 200
A26: Grand Total | B26: 69
